Workbook

Sheet 00_LEIA-ME
A1: WORKBOOK PMBOK 8 · ECOSSISTEMA EXECUTAR
A3: Data de geração | B3: 2026-08-31
A4: Data de corte das fontes | B4: 2026-08-31 — DOCUMENTOS.zip, 214 arquivos
A5: Versão | B5: V1
A6: Base documental | B6: 214 arquivos, 18 classificações MECE (C01–C18), 22 tipos documentais. Integridade verificada por SHA-256: 214/214 casaram com o registro; 202 hashes únicos (12 exemplares duplicados em 9 grupos).
A7: Unidades de análise | B7: ECO-01 App EXECUTAR · ECO-02 Blog Risco Cognitivo · ECO-03 Framework e Metodologia · ECO-04 Produtos Físicos · ECO-05 Infoprodutos · ECO-06 Livro · ECO-07 Consultoria · ECO-08 Ecossistema Creator
A9: REGRA EPISTEMOLÓGICA
A10: Nada foi inventado | B10: Toda afirmação aponta para um documento_id real da base e transcreve a evidência. Ausência de dado virou lacuna descrita, nunca estimativa.
A11: Conflitos preservados | B11: Quando duas fontes divergem, as duas versões ficam registradas com suas fontes. Nenhum conflito foi arbitrado em silêncio.
A12: status (evidência) | B12: fact = evidência explícita · inference = derivação a partir de evidência citada · hypothesis = sem evidência · conflict = fontes incompatíveis · gap = pergunta relevante sem dado
A13: evidence_strength | B13: strong · moderate · weak · none
A15: ABAS
A16: 01_MASTER | B16: Consolidação executiva com contagens calculadas por fórmula sobre as demais abas
A17: 02_AREAS | B17: Os 122 campos do formulário fundido, com status e rastreabilidade
A18: 03_FRAMEWORKS | B18: 279 insights estratégicos: 13 frameworks × 8 unidades
A19: 04_EVIDENCIAS | B19: 680 pares afirmação ↔ documento_id (OUT-54)
A20: 05_HIPOTESES | B20: Hipóteses abertas e o teste que as valida (OUT-55)
A21: 06_RISCOS | B21: Riscos de impacto alto ou em conflito (OUT-57)
A22: 07_DECISOES | B22: Decisões e conflitos não arbitrados (OUT-56)
A23: 08_FONTES | B23: Documentos citados, com sha256 e caminho original (OUT-59)
A24: 09_BACKLOG | B24: Lacunas com a pesquisa necessária para fechar cada uma (OUT-58)
A26: COMO CONTINUAR
A27: Próximo passo | B27: Preencher os dias 3 a 6 do formulário (áreas 11 · 12–17 · 5–7 · 3–4), que somam 77 campos ainda pendentes.
A28: Reprodutibilidade | B28: maestro/scripts/gen_registros_auxiliares.py regenera as abas 04 a 09 a partir dos insights e do formulário. IDs derivam de hash do conteúdo e são estáveis entre execuções.

Sheet 01_MASTER
A1: MASTER · ESTADO DO ECOSSISTEMA
A2: Todas as contagens são fórmulas sobre as demais abas — recalculam ao editar os dados.
A4: COBERTURA DOCUMENTAL
A5: Arquivos na base documental | B5: 214 | C5: C01–C18, 18 classificações MECE, integridade SHA-256 verificada 214/214
A6: Documentos citados como evidência | B6: =COUNTA('08_FONTES'!A2:A87) | C6: Os demais ainda não foram lidos ou são duplicatas/binários
A7: Pares afirmação ↔ documento | B7: =COUNTA('04_EVIDENCIAS'!A2:A681) | C7: Registro de evidência OUT-54
A9: ANÁLISE ESTRATÉGICA — 279 INSIGHTS, 8 UNIDADES
A10: fact | B10: =COUNTIF('03_FRAMEWORKS'!K2:K280,"fact") | C10: Evidência explícita no documento
A11: inference | B11: =COUNTIF('03_FRAMEWORKS'!K2:K280,"inference") | C11: Derivação a partir de evidência citada
A12: conflict | B12: =COUNTIF('03_FRAMEWORKS'!K2:K280,"conflict") | C12: Fontes incompatíveis — preservadas, não arbitradas
A13: hypothesis | B13: =COUNTIF('03_FRAMEWORKS'!K2:K280,"hypothesis") | C13: Sem evidência: precisa de teste
A14: gap | B14: =COUNTIF('03_FRAMEWORKS'!K2:K280,"gap") | C14: Pergunta relevante sem dado na base
A15: Total de insights | B15: =SUM(B10:B14) | C15: Soma dos cinco status acima
A17: FORÇA DA EVIDÊNCIA
A18: strong | B18: =COUNTIF('03_FRAMEWORKS'!I2:I280,"strong") | C18: Fonte primária ou dado interno explícito
A19: moderate | B19: =COUNTIF('03_FRAMEWORKS'!I2:I280,"moderate") | C19: Fonte secundária ou parcial
A20: weak | B20: =COUNTIF('03_FRAMEWORKS'!I2:I280,"weak") | C20: Transcrição de imagem, sem metodologia ou sem data
A21: none | B21: =COUNTIF('03_FRAMEWORKS'!I2:I280,"none") | C21: Sem suporte — vira hipótese ou lacuna
A23: INSIGHTS POR UNIDADE DE ANÁLISE
A24: ECO-01 · App EXECUTAR | B24: =COUNTIF('03_FRAMEWORKS'!C2:C280,"ECO-01")
A25: ECO-02 · Blog Risco Cognitivo | B25: =COUNTIF('03_FRAMEWORKS'!C2:C280,"ECO-02")
A26: ECO-03 · Framework e Metodologia | B26: =COUNTIF('03_FRAMEWORKS'!C2:C280,"ECO-03")
A27: ECO-04 · Produtos Físicos | B27: =COUNTIF('03_FRAMEWORKS'!C2:C280,"ECO-04")
A28: ECO-05 · Infoprodutos | B28: =COUNTIF('03_FRAMEWORKS'!C2:C280,"ECO-05")
A29: ECO-06 · Livro | B29: =COUNTIF('03_FRAMEWORKS'!C2:C280,"ECO-06")
A30: ECO-07 · Consultoria | B30: =COUNTIF('03_FRAMEWORKS'!C2:C280,"ECO-07")
A31: ECO-08 · Ecossistema Creator | B31: =COUNTIF('03_FRAMEWORKS'!C2:C280,"ECO-08")
A33: FORMULÁRIO FUNDACIONAL — 122 CAMPOS
A34: preenchido | B34: =COUNTIF('02_AREAS'!F2:F123,"preenchido") | C34: Resposta sustentada por evidência
A35: parcial | B35: =COUNTIF('02_AREAS'!F2:F123,"parcial") | C35: Resposta existe mas incompleta
A36: lacuna | B36: =COUNTIF('02_AREAS'!F2:F123,"lacuna") | C36: Sem dado na base — lacuna descrita, não TBD
A37: conflito | B37: =COUNTIF('02_AREAS'!F2:F123,"conflito") | C37: Fontes divergentes
A38: pendente | B38: =COUNTIF('02_AREAS'!F2:F123,"pendente") | C38: Ainda não trabalhado (dias 3 a 6)
A39: Total de campos | B39: =SUM(B34:B38)
A40: Completeza dos campos trabalhados | B40: =IFERROR((B34+B35)/(B38-B37),0) | C40: Preenchidos + parciais sobre os campos já trabalhados (exclui os pendentes) — OUT-73
A42: BACKLOG E RISCO
A43: Lacunas registradas | B43: =COUNTA('09_BACKLOG'!A2:A69) | C43: Cada uma com a pesquisa necessária para fechar — OUT-58
A44: Riscos registrados | B44: =COUNTA('06_RISCOS'!A2:A200) | C44: Impacto alto ou em conflito — OUT-57
A45: Decisões e conflitos em aberto | B45: =COUNTA('07_DECISOES'!A2:A31) | C45: Conflitos aparecem como NÃO ARBITRADO — OUT-56
A46: Hipóteses a testar | B46: =COUNTA('05_HIPOTESES'!A2:A7) | C46: Com o teste de validação associado — OUT-55
...

Sheet 02_AREAS
A1: area_id | B1: area | C1: field_id | D1: titulo | E1: origem | F1: status | G1: valor | H1: tipo_informacao | I1: confianca | J1: eco_unit | K1: documento_ids | L1: evidencia | M1: lacuna | N1: proxima_acao
A2: 1 | B2: NEGÓCIO & GTM | C2: 1.1 | D2: Problema central | E2: formulario_original | F2: preenchido | G2: O problema aparece em três camadas distintas, por unidade. (a) ECO-01 App EXECUTAR — problema operacional: “Paralisia por excesso, dificuldade de iniciação das tarefas, não linearidade de execução, troca de contexto cognitivo, retrabalho por não respeitar cadeia única de valor e dependências, memória de trabalho limitada, ausência de processos padronizados e múltiplas fontes de execução e plataformas”. A decisão PROD-03 refina: a dor central é “dificuldade de transformar intenção em comportamento organizado ao longo do tempo”, evitando o posicionamento genérico de “produtividade”; PROD-06 define o problema observável prioritário como a combinação planejamento + memória + tempo + procrastinação. (b) ECO-03 Framework/CERM — problema conceitual: “A distância entre intenção e execução diante de vulnerabilidades cognitivas e demandas reais”; o documento adverte explicitamente para NÃO usar “não execução” como problema principal, por ser estreito demais. (c) ECO-02 Blog Risco Cognitivo — problema estratégico do lançamento editorial: “Apresentar o EXECUTAR cedo demais pode reduzir a credibilidade da investigação e impedir distinguir interesse genuíno pelo problema de interesse no produto”. | H2: fato_interno | I2: alta | J2: TRANSVERSAL (detalhado por ECO-01, ECO-03 e ECO-02) | K2: DOC-C05-001;DOC-C07-009;DOC-C01-005;DOC-C02-039;DOC-C07-002;DOC-C07-010 | L2: DOC-C05-001 (seção “Corpo”, linha Problema): “Paralisia por excesso, dificuldade de iniciação das tarefas, não linearidade de execução, troca de contexto cognitivo, retrabalho por não respeitar cadeia única de valor e dependências, memória de trabalho limitada, ausência de processos padronizados e múltiplas fontes de execução e plataformas.” Perspectiva do usuário no mesmo documento: “Perco dinheiro e oportunidades por atrasos e desorganização. […] O momento de maior ansiedade e aflição são os primeiros 30 minutos iniciais, pois não sei onde estava ontem, o que devo fazer agora e como sei que terminei.” | DOC-C07-009 (decisão PROD-03): “Definir a dor central como dificuldade de transformar intenção em comportamento organizado ao longo do tempo, evitando o posicionamento genérico de ‘produtividade’.” | DOC-C01-005: “Eu evitaria usar não execução como problema principal. É estreito demais.” e “A distância entre intenção e execução diante de vulnerabilidades cognitivas e demandas reais.” | DOC-C02-039 (BMC, célula Problema): “Apresentar o EXECUTAR cedo demais pode reduzir a credibilidade da investigação e impedir distinguir interesse genuíno pelo problema de interesse no produto.” | N2: Registrar no formulário um enunciado de problema por unidade, em vez de fundir as três camadas num único texto.
A3: 1 | B3: NEGÓCIO & GTM | C3: 1.2 | D3: Público-alvo / ICP | E3: formulario_original | F3: conflito | G3: CONFLITO ENTRE DOCUMENTOS. Versão A (DOC-C05-001, workbook Sas-06, seção Público): “Homens, adultos, neurodivergentes, autônomos, na faixa dos 25–35 anos, recém-diagnosticados, que gerenciam múltiplos processos e projetos ao mesmo tempo. Têm consciência básica de terminologia e funções executivas, já utilizaram e abandonaram outros aplicativos por não manterem o uso e rejeitam alta complexidade de configuração.” Versão B (DOC-C07-009, decisão ICP-01 / achado ICP-HYP-01, 15/08/2026): “Profissional independente/solo brasileiro, aproximadamente 25–44 anos, multiprojeto, que perde contexto, tem dificuldade recorrente para escolher próxima ação, já tentou ferramentas de produtividade e controla/influencia a própria compra”, com ressalva explícita de que diagnóstico de TDAH NÃO é critério de entrada. As duas versões divergem em faixa etária (25–35 × 25–44), gênero (homens × não especificado) e no papel da neurodivergência/diagnóstico como critério de ICP. Unidades com público próprio já declarado: ECO-07 Estúdio — “Profissionais solo, autônomos e pequenos negócios com trabalho, informação, clientes e projetos dispersos”; ECO-02 Blog — “Leitores interessados em funções executivas, neurodivergência, trabalho, projetos e risco; especialistas entram como crítica externa, não como endosso.” | H3: decisao | I3: alta | J3: TRANSVERSAL — conflito em ECO-01; ECO-07 e ECO-02 têm públicos próprios | K3: DOC-C05-001;DOC-C07-009;DOC-C02-039 | L3: DOC-C05-001: “Homens, adultos, neurodivergentes, autônomos, na faixa dos 25–35 anos, recém-diagnosticados…” | DOC-C07-009 (ICP-01, status DECIDED_FOR_TEST, confiança MÉDIA-ALTA): “Iniciar testes por profissionais independentes multiprojeto, sem exigir diagnóstico de TDAH”; e “O que não é critério de entrada: Diagnóstico de TDAH. Diagnóstico/autodeclaração deve ser variável opcional posterior, especialmente porque dados de saúde são sensíveis e não são necessários para o core funcional.” | DOC-C05-001 (SSOT Executar Studio, item 02 Público): “Profissionais solo, autônomos e pequenos negócios com trabalho, informação, clientes e projetos dispersos.” | DOC-C02-039 (BMC, Público/validação): “Leitores interessados em funções executivas, neurodivergência, trabalho, projetos e risco.” | M3: Não há registro de qual definição prevalece nem data de supersessão. DOC-C07-009 é de 15/08/2026 e classifica o ICP como hipótese de classe E a validar; DOC-C05-001 não traz data própria de decisão. Faltaria um ADR comercial ou nota de decisão datada. | N3: Decidir explicitamente qual ICP vale para o lançamento de 07/09 e arquivar a versão superada com data e justificativa.
A4: 1 | B4: NEGÓCIO & GTM | C4: 1.3 | D4: Proposta de valor | E4: formulario_original | F4: preenchido | G4: Proposta de valor por unidade. ECO-01 App: “Criar uma situação em que a execução do que foi planejado aconteça com o mínimo possível de carga administrativa e cognitiva sobre o usuário. O sistema assume parte da estrutura, organização e priorização”; promessa: “Zero configuração, mínimo de personalização, uso mínimo do app — cerca de 1–2 vezes por semana — e externalização cognitiva”; mensagem de sustentação: “Você executa. O sistema sustenta a execução.”; headline canônica: “O app de produtividade feito para você não usar.” Posicionamento resultante (DOC-C07-009): “Sistema de execução para profissionais multiprojeto que transforma contexto em próxima ação e preserva o estado do trabalho — neurocompatível por design, mas não apresentado como tratamento de TDAH.” ECO-07 Estúdio: “Traga o problema. Em 7 dias, saia com um sistema funcionando”; “Menos tempo organizando a operação. Mais clareza sobre o que fazer, onde encontrar e como repetir.” ECO-02/ECO-03: “Transformar Risco Cognitivo em uma categoria editorial e investigável antes de conectá-la ao produto.” ECO-05 Infoprodutos: “Livros digitais funcionam como produto de entrada e aplicação. Curso funciona como aplicação guiada.” ECO-04 Físicos: “Neurobook = planejar e registrar → Timer = executar → Organização = reduzir decisões cotidianas → Office Kit = sistema integrado.” | H4: fato_interno | I4: alta | J4: TRANSVERSAL — respostas distintas em ECO-01, ECO-07, ECO-02/03, ECO-05 e ECO-04 | K4: DOC-C05-001;DOC-C07-009;DOC-C09-004;DOC-C09-006;DOC-C09-016;DOC-C09-008;DOC-C02-039 | L4: DOC-C05-001 (Benefício e Promessa principal; Mensagem final): “O usuário executa. O sistema sustenta a execução.”; Headline 01: “O app de produtividade feito para você não usar.”; Descrição 01: “Executar é um sistema de gestão de projetos orientado à execução que reduz configuração, organização manual e decisões repetitivas para mostrar o que pode ser feito agora.” | DOC-C07-009 (campo positioning): “Sistema de execução para profissionais multiprojeto que transforma contexto em próxima ação e preserva o estado do trabalho.” | DOC-C09-004: “O aplicativo de produtividade feito para você usar menos. O sistema sustenta a estrutura; o usuário executa.” | DOC-C09-006: “Traga o problema. Em 7 dias, saia com um sistema funcionando.” | DOC-C02-039 (BMC, Proposta de valor): “Transformar Risco Cognitivo em uma categoria editorial e investigável antes de conectá-la ao produto.”
A5: 1 | B5: NEGÓCIO & GTM | C5: 1.4 | D5: Canais de aquisição | E5: formulario_original | F5: preenchido | G5: Arquitetura de canais em dois níveis (DOC-C05-001). OWNED: 01 executar.com/Blog (fonte canônica do conteúdo); 02 Biblioteca Executar (indexação permanente, guias, referências, e-books); 03 e-mail/newsletter; 04 comunidade futura. DISTRIBUIÇÃO (plataformas alugadas/terceiras): YouTube (explicação + demonstração + descoberta), Instagram (carrossel, visual, Reels), TikTok (descoberta, vídeos curtos), LinkedIn (gestão, operações, risco, conteúdo técnico). Regra de produção “uma fonte, vários outputs”: questão editorial → pesquisa → artigo canônico → diagrama/infográfico → vídeo principal → 2–4 shorts → carrossel → post LinkedIn → newsletter → entrada na Biblioteca → trecho no e-book/curso → CTA de aprofundamento. Canais comerciais: Hotmart (infoprodutos, com cadastro e checkout), afiliados (Barkley ×2 e Ana Beatriz Barbosa Silva), loja própria, formulário visual do Estúdio. Aquisição do ECO-07: “Conteúdo → Showroom → Formulário visual → Encontro → Projeto”. Operacionalmente, os canais estão registrados como 10 chamadas CH-001…CH-010 com destino e estado (DOC-C08-004) e 10 rotas RT-001…RT-010 (DOC-C08-006). Para ECO-02, o canal inaugural é o pacote de 18 ativos em 14 dias: 1 artigo, 1 newsletter, 1 vídeo principal, 3 vídeos curtos, 2 carrosséis, 6 posts curtos, 1 infográfico, 1 checklist, 1 lead magnet e 1 landing page. | H5: decisao | I5: alta | J5: TRANSVERSAL | K5: DOC-C05-001;DOC-C08-004;DOC-C08-006;DOC-C06-001;DOC-C02-043;DOC-C09-015;DOC-C09-018;DOC-C12-004 | L5: DOC-C05-001 (Arquitetura das plataformas): “OWNED 01 executar.com / Blog — Fonte canônica do conteúdo; OWNED 02 Biblioteca Executar; OWNED 03 E-mail / newsletter; DISTRIBUIÇÃO 01 YouTube; 02 Instagram; 03 TikTok; 04 LinkedIn”; e “Instagram, YouTube, TikTok e LinkedIn não são plataformas proprietárias; são plataformas alugadas/terceiras.” | DOC-C05-001 (SSOT Studio, item 13 Aquisição): “Conteúdo → Showroom → Formulário visual → Encontro → Projeto.” | DOC-C08-004: “CH-001 Experimentar Executar → página do aplicativo”, “CH-003 Explorar a biblioteca”, “CH-007 Ver o livro → ligação de afiliado”, “CH-010 Entrar na lista → formulário”. | DOC-C02-043: “Pacote: 1 artigo, 1 newsletter, 1 vídeo principal, 3 vídeos curtos, 2 carrosséis, 6 posts curtos, 1 infográfico, 1 checklist, 1 lead magnet e 1 landing page — 18 ativos principais.” | DOC-C09-018: “Núcleo inicial — Russell A. Barkley · Vencendo o TDAH Adulto; Russell A. Barkley · Executive Functions; Ana Beatriz Barbosa Silva · Mentes Inquietas.” | M5: Nenhum documento define mídia paga, verba por canal ou meta de tráfego. A aquisição paga só aparece implicitamente, como pressuposto do guardrail de CAC em DOC-C07-009. | N5: Decidir se haverá mídia paga no lançamento de 07/09 e, em caso afirmativo, registrar acquisition_source e campaign_id por canal — eventos já especificados na telemetria de DOC-C07-009.
A6: 1 | B6: NEGÓCIO & GTM | C6: 1.5 | D6: Métrica North Star | E6: formulario_original | F6: parcial | G6: Nenhum documento nomeia uma “métrica North Star”. O candidato canônico mais próximo é o VALUE_EVENT-01 da telemetria do EXECUTAR: “Projeto real → contexto interpretado → próxima ação válida → ação executada → conclusão/evidência registrada” — o evento que define valor entregue e que governa ativação, PMF e coortes W1/W2/W4/W8. Os endpoints de eficácia funcional associados são time_to_next_action, resume_latency, completion_rate, context_reconstruction, execution_cycles_per_week e abandonment_rate. Para ECO-02, a meta declarada é de output, não de outcome: “publicar 18 ativos em 14 dias, com artigo dentro de 1.200–1.800 palavras”, capturando baseline de visualizações, retenção, salvamentos, inscrições e downloads — com a regra explícita de “não estabelecer ainda metas arbitrárias de seguidores ou leads sem baseline”. O BMC do ECO-02 registra literalmente “% geral não informado” e “métricas não informadas permanecem desconhecidas”. | H6: inferencia | I6: media | J6: ECO-01 (candidato VALUE_EVENT-01) e ECO-02 (meta de output) | K6: DOC-C07-009;DOC-C02-043;DOC-C02-039;DOC-C16-003;DOC-C16-006 | L6: DOC-C07-009 (objeto telemetry): “value_event_01: Projeto real → contexto interpretado → próxima ação válida → ação executada → conclusão/evidência registrada”; “functional_efficacy_endpoints: time_to_next_action, resume_latency, completion_rate, context_reconstruction, execution_cycles_per_week, abandonment_rate.” | DOC-C02-043 (Objetivo SMART da primeira fase): “Mensurável: publicar 18 ativos em 14 dias, com artigo dentro de 1.200–1.800 palavras”; “Não estabelecer ainda metas arbitrárias de seguidores ou leads sem baseline.” | DOC-C02-039 (rodapé do BMC): “métricas não informadas permanecem desconhecidas”. | DOC-C16-003 (MED-001) lista apenas o que verificar (chamada→destino, formulário→recebimento, download→arquivo), sem métrica-alvo. | M6: Falta a eleição formal de UMA métrica North Star com definição, fórmula, janela de medição e meta. O artefato estaria num documento de métricas/analytics ou num ADR de produto — inexistente no corpus. | N6: Eleger “VALUE_EVENT-01 concluídos por usuário ativo por semana” como NSM candidata e fixar baseline após o piloto de ≥40 usuários previsto em PMF-01.
A7: 1 | B7: NEGÓCIO & GTM | C7: 1.6 | D7: Métricas guardrail | E7: formulario_original | F7: preenchido | G7: Guardrails existentes, por domínio. (a) Econômico — CAC-01: TARGET-CAC provisório ≤ R$70 e alerta/limite de aproximadamente R$95 até existir CAC observado. (b) Regulatório e de comunicação — CLAIM-01, PROD-14 e PROD-15: claims proibidos hoje são “Reduz sintomas de TDAH”, “Melhora função executiva clinicamente”, “Trata TDAH”, “Diagnostica ou identifica TDAH”, “Substitui terapia, tratamento ou medicação” e “Cientificamente comprovado para TDAH”; e é bloqueado qualquer uso do produto como diagnóstico, substituição profissional ou inferência clínica. (c) Gate de PMF — PMF-01: só declarar PMF com convergência de VALUE_EVENT-01, coortes W1/W2/W4/W8, pagamento/renovação e pesquisa de dependência, com heurística n ≥ 40 qualificados e > 40% “muito desapontados”. (d) Operacional de lançamento: “Broken links = 0”, “backlog crítico = 0”, “não existe entrega crítica aguardando produção”. (e) Epistemológico — invariantes: “original ≠ extração ≠ evidência ≠ decisão · candidate ≠ verified · benchmark ≠ dado do EXECUTAR · modelo econômico ≠ unit economics observado · literatura externa ≠ eficácia do EXECUTAR · similaridade ≠ suporte factual”. | H7: decisao | I7: alta | J7: TRANSVERSAL — econômico e de claims em ECO-01; operacional no GTM 07/09 | K7: DOC-C07-009;DOC-C06-001;DOC-C08-007 | L7: DOC-C07-009 (CAC-01): “Usar TARGET-CAC provisório ≤ R$70 e alerta/limite de aproximadamente R$95 até existir CAC observado.” | DOC-C07-009 (claims_policy.prohibited_now): lista literal dos seis claims proibidos. | DOC-C07-009 (Invariantes): “modelo econômico ≠ unit economics observado”. | DOC-C06-001 (D11, DoD do dia): “Broken links = 0; fluxo de conversão testado”; D12: “Tudo agendado; backlog crítico = 0; GTM READY.” | DOC-C08-007: “não existe entrega crítica aguardando produção.” | M7: Não há guardrail técnico de produto nesta área (taxa de erro, latência, custo de IA por usuário). O evento variable_ai_cost é coletado na especificação de telemetria, mas sem limiar definido. | N7: Definir limite para variable_ai_cost por usuário ativo, já que o evento está previsto mas não tem teto declarado.
A8: 1 | B8: NEGÓCIO & GTM | C8: 1.7 | D8: CAC (custo de aquisição) | E8: formulario_original | F8: parcial | G8: Não existe CAC observado. Existe apenas guardrail modelado: TARGET-CAC provisório ≤ R$70 (alvo conservador) e alerta/limite de aproximadamente R$95 (cenário-base); e CAC máximo por cenário para manter LTV:CAC = 3 em R$141 (otimista), R$94 (base) e R$71 (conservador). O próprio documento fixa a regra de cálculo e proíbe substitutos: “CAC observado = gasto atribuível / novos clientes pagantes. CPI, CPM, clique e cadastro não substituem CAC.” Classe epistêmica E (inferido), status DECIDED_AS_GUARDRAIL, confiança MÉDIA na fonte. | H8: hipotese | I8: media | J8: ECO-01 | K8: DOC-C07-009 | L8: DOC-C07-009 (bloco “CAC guardrail”): “≤ R$70 alvo conservador; ≈ R$95 alerta / cenário-base. CAC observado = gasto atribuível / novos clientes pagantes. CPI, CPM, clique e cadastro não substituem CAC.” | Achado CAC-HYP-01 (epistemic_class E, status MODEL_GUARDRAIL): “Guardrail econômico; CAC observado só existe após campanha e aquisição pagante.” | Gap registrado: {gap: CAC, status: “MODELO + GUARDRAIL”, closed: false, remaining: “Campanhas e clientes pagantes.”} | M8: Falta o CAC real. Não há, em nenhum dos 214 arquivos, campanha paga executada, cliente pagante registrado ou tabela de gasto por canal. O dado nasceria dos eventos acquisition_source, campaign_id e paid_at do warehouse de telemetria — já especificados, ainda não instrumentados. | N8: Não preencher com número. Instrumentar acquisition_source/campaign_id/paid_at antes da primeira campanha paga e só então calcular CAC observado.
A9: 1 | B9: NEGÓCIO & GTM | C9: 1.8 | D9: LTV (valor do tempo de vida) | E9: formulario_original | F9: parcial | G9: Não existe LTV observado. Existe apenas LTV modelado sob premissas declaradas como classe E: ARPU mensal de R$49,90 e margem bruta assumida de 85%; cenário otimista com churn mensal de 10% → LTV R$424; cenário base com churn de 15% → LTV R$282,77; cenário conservador com churn de 20% → LTV R$212. O documento instrui explicitamente: “Não persistir como LTV factual. Substituir por cohorts LTV_30/60/90/180/365.” | H9: hipotese | I9: media | J9: ECO-01 | K9: DOC-C07-009 | L9: DOC-C07-009 (unit_economics, status MODEL_HYPOTHESIS_NOT_OBSERVED): “arpu_monthly_brl: 49.9; gross_margin_assumption: 0.85; scenarios: optimistic churn 0.10 → ltv 424; base churn 0.15 → ltv 282.77; conservative churn 0.20 → ltv 212.” | Achado LTV-HYP-01: “LTV_MODEL_BASE ≈ R$282,77 sob ARPU R$49,90, margem bruta 85% e churn mensal 15%. […] Não persistir como LTV factual.” | Gap registrado: {gap: LTV, status: “MODELO HIPOTÉTICO”, closed: false, remaining: “Retenção, churn e margem reais.”} | M9: Falta LTV factual: não há coorte real, churn observado nem pagamento registrado. O dado nasceria das janelas LTV_30/60/90/180/365 do warehouse de telemetria, especificadas mas não populadas. | N9: Não preencher com número. Rodar as coortes LTV_30/60/90 após o primeiro piloto pagante e substituir o modelo.
A10: 1 | B10: NEGÓCIO & GTM | C10: 1.9 | D10: Margem por unidade/usuário | E10: formulario_original | F10: parcial | G10: Há regra de margem, não margem observada, e ela difere por unidade. ECO-01 App: margem bruta de 85% é premissa (classe E) do modelo econômico, não medição. ECO-05 Infoprodutos: a margem deve nascer da cadeia “valor percebido → benchmark → posicionamento → taxa do canal → CAC → margem de contribuição”, com taxa Hotmart projetada por prudência em 9,9% + R$2,49 (a Central de Ajuda ainda mostrava 9,9% + R$1,00, com mudança anunciada para 21/09/2026). ECO-04 Produtos físicos: a margem deve nascer do custo variável total Y, nunca do preço de fornecedor — a planilha de landed cost do Timer 45 parte de R$39 de fornecedor e mantém “preencher” em frete internacional, impostos/importação, frete/localização, embalagem Executar e etiqueta/manual/QR; fórmulas registradas: “Margem bruta = (Preço − Custo) ÷ Preço” e “Markup = Preço ÷ Custo”. Política de margem declarada como a testar, sem percentual fixado: “Eu não fixaria ainda ‘o Timer precisa dar 60%’ ou ‘o Neurobook precisa dar 50%’”, com estratégia diferenciada por classe (Timer = produto comparável, margem disciplinada; Neurobook = proprietário, maior liberdade de preço; Office Kit = bundle, maximizar margem absoluta e ticket, não percentual). | H10: decisao | I10: media | J10: TRANSVERSAL — ECO-01 (premissa 85%), ECO-05 (taxa de canal), ECO-04 (landed cost incompleto) | K10: DOC-C07-009;DOC-C05-001;DOC-C09-008 | L10: DOC-C07-009: “gross_margin_assumption: 0.85”, dentro de unit_economics com status MODEL_HYPOTHESIS_NOT_OBSERVED. | DOC-C05-001 (Hotmart e margem): “a página comercial da Hotmart já anuncia 9,9% + R$2,49. Eu faria suas projeções usando 9,9% + R$2,49, por prudência”; e “valor percebido → benchmark → posicionamento → taxa do canal → CAC → margem de contribuição.” | DOC-C05-001 (Unit Economics — produtos físicos): tabela do Timer 45 com “Preço do fornecedor R$39” e cinco linhas “preencher”; “O preço deve nascer de Y, e não dos R$39.” | DOC-C09-008: “Timer 45 | ferramenta funcional | validar custo e preço”. | M10: Faltam os custos posto (landed cost) reais dos SKUs físicos — as linhas estão literalmente marcadas “preencher” — e falta a margem observada por usuário do app (custo de infraestrutura + variable_ai_cost por usuário ativo). Estaria numa planilha de custo de produto e num relatório de custo por usuário. | N10: Cotar frete, impostos e embalagem dos quatro SKUs para fechar o Y do Timer 45 antes de publicar preço na loja.
A11: 1 | B11: NEGÓCIO & GTM | C11: 1.10 | D11: Ponto de equilíbrio (breakeven) | E11: formulario_original | F11: lacuna | H11: fato_interno | I11: alta | J11: TRANSVERSAL | K11: DOC-C04-001;DOC-C07-009;DOC-C05-001 | L11: Busca literal por “break-even”, “breakeven” e “ponto de equilíbrio” em todos os 214 arquivos retorna um único hit: DOC-C04-001 (Cronograma.md), que é o cronograma do próprio formulário e apenas lista o nome do campo — “1.10 | Ponto de equilíbrio (breakeven) | formulário”. DOC-C07-009, o documento econômico mais avançado do corpus, cobre preço, CAC, LTV e PMF, mas não calcula breakeven, e classifica todo o bloco de unit economics como MODEL_HYPOTHESIS_NOT_OBSERVED. DOC-C05-001 discute margem, markup e capital de giro, mas nunca ponto de equilíbrio. | M11: Falta qualquer cálculo de ponto de equilíbrio: não há custo fixo mensal declarado (infraestrutura, ferramentas, Hotmart, domínios), não há meta de assinantes pagantes e não há receita atual registrada. O dado estaria numa planilha de custos fixos + modelo de receita, ou num P&L simplificado — inexistentes no corpus. | N11: Levantar o custo fixo mensal real (Vercel, Neon, Clerk, Sentry, domínios, Hotmart) e dividi-lo pela margem de contribuição por assinante para obter o número mínimo de assinantes; não estimar antes desse levantamento.
A12: 1 | B12: NEGÓCIO & GTM | C12: 1.11 | D12: Teto de gasto de infraestrutura | E12: formulario_original | F12: lacuna | H12: fato_interno | I12: alta | J12: ECO-01 (e ECO-02, site/CMS) | K12: DOC-C04-002;DOC-C02-017;DOC-C07-009 | L12: A infraestrutura está nomeada em vários documentos — DOC-C04-002 cita monorepo com bun, apps/app em Next.js, apps/mobile em Expo 57, Clerk, Sentry, Vercel Preview, “AWS/Aurora” e app local-first via localStorage; DOC-C02-017 cita “Vercel Payload Website Starter + Next.js + Payload CMS + PostgreSQL/Neon + Vercel Blob”, mais “Vercel Web Analytics + Speed Insights”. Nenhum desses documentos, nem DOC-C07-009, declara valor monetário de gasto de infraestrutura ou teto. Busca por “teto de gasto”, “custo de infra”, “orçamento de infra”, “free tier” e “plano gratuito” em todo o corpus não retorna ocorrências. | M12: Falta o teto de gasto: nenhum documento traz fatura, plano contratado (Hobby/Pro), limite de billing ou alerta de custo de qualquer fornecedor. O dado estaria nos consoles/faturas de Vercel, Neon, Clerk e Sentry, ou num documento de orçamento de infraestrutura. | N12: Exportar o custo mensal atual de cada fornecedor e definir um teto explícito com alerta de billing antes do lançamento de 07/09.
A13: 1 | B13: NEGÓCIO & GTM | C13: 1.12 | D13: Gatilhos de upgrade de infra | E13: formulario_original | F13: lacuna | H13: fato_interno | I13: media | J13: ECO-01 | K13: DOC-C04-002;DOC-C07-009 | L13: Não há gatilho de upgrade de infraestrutura em nenhum documento lido. O único enunciado adjacente é uma decisão de sequenciamento arquitetural, não um gatilho de escala: DOC-C04-002 registra “Integrar o núcleo ao Vercel AI SDK, MCP authority, Clerk e UnitOfWork local antes de Aurora” e “App é local-first: EstadoOperacional hidrata de localStorage via chaveOrganizacao + restaurarEstado, sincroniza com servidor só opcionalmente (remotePersistenceAvailable)”. DOC-C07-009 prevê coletar variable_ai_cost, mas não define limiar de disparo. | M13: Falta o gatilho: não existe métrica-limiar (usuários ativos, requisições, GB de banco, custo mensal, p95 de latência) associada a uma ação de upgrade. O dado estaria num runbook de capacidade/escalabilidade ou num ADR de infraestrutura. | N13: Definir dois ou três limiares objetivos (custo mensal, conexões de banco, p95) que disparem a migração de local-first para persistência remota/Aurora, e registrá-los como ADR.
A14: 1 | B14: NEGÓCIO & GTM | C14: 1.13 | D14: Análise competitiva | E14: enriquecido_via_plugin | F14: preenchido | G14: Há análise competitiva em três frentes, todas com preços e fontes registrados. (a) ECO-05 Infoprodutos — benchmark de e-books: ofertas de TDAH observadas a R$19,90, R$27, R$29,90 e R$37,90, e um e-book comercial da Artmed de Barkley a R$97,28; faixas de posicionamento recomendadas de R$19,90–29,90 (PDF simples) até R$99–129 (bundle de 3 e-books). Benchmark de cursos: curso introdutório 12h/16 aulas a R$89,90; curso neurodivergência/trabalho 15+ aulas a R$97; escola ampla com 200+ aulas a R$197; programa Ana Beatriz a ~R$196; programa guiado de 7 encontros a R$197; programa premium “TDAH 2.0” (90 dias, 75 aulas, app/IA) a R$1.997. (b) ECO-07 Estúdio — benchmark de consultoria: CCN a R$300/h com implantação conduzida; Produtive.Me a R$2.500 por sprint de mapeamento de 15 dias e R$4.000 por 30 dias, sem implementação; benchmark de Work OS usado para decidir vender “transformação operacional”, não “consultoria de Notion”. (c) ECO-03 Framework — prior art: ICF/CIF e WHODAS 2.0 da OMS, Roadmap to Self-Empowerment for Autistic Adults, My Sensory Experiences Tool, ICF Core Sets para autismo e TDAH, “cognitive risk” já existente em ERM, publicação da APM de 26/08/2026 e pesquisa da APM sobre neurodiversidade em project management. Guardrail explícito: “‘Não encontramos’ não significa ‘não existe’.” | H14: evidencia_externa | I14: alta | J14: TRANSVERSAL — forte em ECO-05, ECO-07 e ECO-03; fraco em ECO-01 | K14: DOC-C05-001;DOC-C01-005;DOC-C02-031;DOC-C02-022;DOC-C07-009 | L14: DOC-C05-001 (Benchmark — e-books): “Há ofertas de TDAH por R$ 19,90, R$ 27, R$ 29,90 e R$ 37,90; um e-book comercial da Artmed de Barkley, muito mais extenso e editorialmente tradicional, está em R$ 97,28.” (Benchmark — curso): tabela com seis ofertas de R$89,90 a R$1.997. (Serviços): “a CCN mantém consultoria a R$300/h […]; a Produtive.Me cobra R$2.500 por um sprint de mapeamento de 15 dias e R$4.000 por 30 dias, sem implementação.” | DOC-C01-005: “O framework mais próximo, em termos de estrutura geral, é a ICF/CIF da OMS”; “Há também o WHODAS 2.0, da OMS”. | DOC-C02-031 (item 4, GUARDRAIL): “‘Não encontramos’ não significa ‘não existe’.” | DOC-C02-022 (RC-014): “A APM publicou em 26/08/2026 conteúdo dizendo que projetos também podem falhar cognitivamente.” | DOC-C07-009 (themes_qt): tema “Benchmark de apps concorrentes” com apenas 3 registros. | M14: A análise competitiva do ECO-01 é a mais fraca: apps concorrentes (Notion, ClickUp, Trello, Todoist e similares) aparecem apenas como ferramentas que o cliente já usa, sem comparativo de features, preço ou posicionamento — e a base de evidências tem só 3 registros no tema “Benchmark de apps concorrentes”. | N14: Produzir um comparativo direto de apps concorrentes com preço, modelo de assinatura e tratamento de “próxima ação”, para sustentar o posicionamento de PRICE-01.
A15: 1 | B15: NEGÓCIO & GTM | C15: 1.14 | D15: Dados e warehouse | E15: enriquecido_via_plugin | F15: preenchido | G15: Existe arquitetura de dados documentada em cinco camadas. (a) Base de evidências: base_evidencias_tdah_adulto_WAREHOUSE.json, que encapsula um CSV — file_name base_evidencias_tdah_adulto_WAREHOUSE.csv, sha256 57f2a101…cffdbf, 129.719 bytes, 30 colunas, 240 registros. (b) Canônico e schema: “Google Drive / Supabase-2026-TDHA”, schema_version “DATA-SCHEMA-002 / base 1.1”; estado atual com 31 sources, 248 RAW, 116 knowledge, 161 evidence candidates, 0 strict VERIFIED, 240 evidências legadas, 694 perguntas de framework e 22 decisões operacionais. Gate factual definido: “record_status=VERIFIED · classe A/B/C · source_verified · extraction_verified · context_verified · proveniência · numeric_verified para measurement”. (c) Schema de domínio: SCHEMA_MATRIZ_GESTAO_TDAH_V1 (CSV + YAML), 18 campos, origem DATA-ADHD-PM-001/DRIVE-PROD-002, estado documental “existente + registrado + verificado; não preenchido; não aprovado como schema final”. (d) Telemetria de produto especificada e não instrumentada: acquisition_source, campaign_id, install_or_signup, activated_at, first_value_at, paid_at, plan, gross_revenue, refund, variable_ai_cost, cancelled_at, renewed_at, last_value_event_at; coortes W1/W2/W4/W8; janelas LTV_30/60/90/180/365. (e) Observabilidade editorial: Vercel Web Analytics + Speed Insights, com decisão RC-054 de priorizar métricas agregadas em vez de identificação individual. | H15: fato_interno | I15: alta | J15: TRANSVERSAL | K15: DOC-C07-007;DOC-C07-009;DOC-C07-005;DOC-C07-006;DOC-C02-017 | L15: DOC-C07-007 (cabeçalho do JSON): “format: csv · file_name: base_evidencias_tdah_adulto_WAREHOUSE.csv · sha256: 57f2a1015cf04e67fba04178e038f8d31f617d6e0ec050711280c8b048cffdbf · size_bytes: 129719 · columns: 30 · row_count: 240”. | DOC-C07-009 (status): “canonical: Google Drive / Supabase-2026-TDHA · schema_version: DATA-SCHEMA-002 / base 1.1”; (Estado atual): “31 sources · 248 RAW · 116 knowledge · 161 evidence candidates · 0 strict verified · 22 decisões operacionais.” | DOC-C07-006: “estado_documental: existente + registrado + verificado; não preenchido; não aprovado como schema final”. | DOC-C02-017 (OBSERVABILIDADE): “Vercel Web Analytics + Speed Insights”; RC-054: “Inicialmente priorizar métricas agregadas, não identificação…”. | M15: O warehouse cobre evidência científica, não dados de produto: são 0 registros strict VERIFIED e nenhum evento de telemetria do app foi coletado — a lista de required_events é especificação, não dado. | N15: Instrumentar os 13 required_events antes do lançamento, para que CAC, LTV e PMF possam migrar de modelo para observação.
A16: 1 | B16: NEGÓCIO & GTM | C16: 1.15 | D16: Cadência financeira recorrente | E16: enriquecido_via_plugin | F16: lacuna | H16: fato_interno | I16: alta | J16: TRANSVERSAL | K16: DOC-C04-001;DOC-C06-001;DOC-C07-009;DOC-C07-010 | L16: Busca por “DRE”, “P&L”, “demonstrativo de resultado”, “variância”, “fluxo de caixa” e “MRR” em todo o corpus retorna apenas: DOC-C04-001 (Cronograma.md), que só lista o nome do campo “1.15 | Cadência financeira recorrente (P&L/variância) | 🔌 finance/financial-statements, variance-analysis”, e ocorrências em outro sentido (variância estatística, gates operacionais). Existe cadência OPERACIONAL detalhada — DOC-C06-001 define templates diário e semanal, WEEK-01/WEEK-02, gates G0–G9, DoD diário e somatório de horas por value stream — mas nenhuma cadência FINANCEIRA: não há fechamento mensal, revisão de receita e custo, nem análise de variância orçado × realizado. | M16: Falta a rotina financeira recorrente: quem fecha, com que periodicidade, contra qual orçamento e em qual artefato. O dado estaria num P&L/planilha financeira mensal ou num runbook de fechamento — inexistentes no corpus. | N16: Instituir um fechamento mensal simples (receita por canal, custo fixo, custo variável de IA/infra, margem) assim que houver a primeira venda; hoje não há receita registrada que justifique análise de variância.
A17: 1 | B17: NEGÓCIO & GTM | C17: 1.16 | D17: Pipeline e forecast de vendas | E17: enriquecido_via_plugin | F17: parcial | G17: Há pipeline definido para ECO-07 (Estúdio) e nenhum forecast quantificado em nenhuma unidade. Pipeline do Estúdio: “Conteúdo → problema reconhecido → showroom demonstra solução concreta → formulário visual de 5 min → seleção de fit → D1 entender + cocriar → D2–D3 estruturar + construir → D4 demonstrar protótipo → D5 Studio + teste assíncrono → D6 implementar + onboarding → D7 validar → 10/20/30 manutenção → caso + evidência → novo projeto / indicação / expansão”. Capacidade declarada: 1 cliente por semana, 1 projeto, 1 entrega principal, 7 dias. Escada comercial que funciona como estágio de pipeline: Piloto 01–03 a R$0 (para construir processo, métricas e portfólio) → Founding 04–06 a R$700 (primeiros clientes pagantes) → Regular Workflow a partir de R$1.490, Automação/Agente a partir de R$1.990, App/Sistema a partir de R$2.490. A qualificação é capturada no FORM-001, que inclui “prazo desejado” e “faixa de investimento” (Até R$1.500 · R$1.500–2.500 · R$2.500–5.000 · Ainda não sei), além da tabela de fit “É para / Não é para”. | H17: decisao | I17: media | J17: ECO-07 (pipeline definido); forecast ausente em todas as unidades | K17: DOC-C05-001;DOC-C12-003;DOC-C09-006;DOC-C11-010 | L17: DOC-C05-001 (Cadeia única de valor final): “Conteúdo ↓ problema reconhecido ↓ showroom demonstra solução concreta ↓ formulário visual de 5 min ↓ seleção de fit ↓ D1 · entender + cocriar […] ↓ caso + evidência ↓ novo projeto / indicação / expansão.” (Escada recomendada): “Piloto 01–03 · R$0; Founding 04–06 · R$700; Regular Workflow · desde R$1.490; Regular Automação/Agente · desde R$1.990; Regular App/Sistema · desde R$2.490.” | DOC-C09-006 (Modelo): “1 cliente por semana · 1 projeto · 1 entrega principal · 7 dias.” | DOC-C12-003: “10 · Faixa de investimento imaginada: Até R$1.500 · R$1.500–2.500 · R$2.500–5.000 · Ainda não sei.” | M17: Falta o forecast: não há número esperado de leads, taxa de conversão por estágio, ticket médio projetado nem receita prevista por mês. E não há pipeline algum para ECO-01 (assinaturas) nem ECO-05 (infoprodutos). O dado estaria num CRM ou planilha de forecast — inexistentes no corpus. | N17: Instrumentar o FORM-001 para contar leads por estágio a partir de 07/09 e só então projetar conversão, dado que a capacidade está travada em 1 cliente por semana.
A18: 2 | B18: PRODUTO | C18: 2.1 | D18: Nome do produto/feature | E18: formulario_original | F18: preenchido | G18: Nomes canônicos por unidade. ECO-01 — produto: EXECUTAR (grafado “Executar”), com três features de destaque: Feature 01 Agente 007 / Autogestão adaptativa; Feature 02 Scanner / QR / Atalhos; Feature 03 Mapa-OS / Analógico / Prisma. No código, a identidade unificada chama-se “tokens exec.*” e as rotas entregues são /scanner e /mapa-os (formatos ?format=prisma, A4 retrato, e ?format=tripe, A4 paisagem). ECO-07: “Executar Studio”, com três famílias — 01 Processos & Workflows, 02 Automações & Agentes, 03 Apps & Sistemas de Trabalho. ECO-02/ECO-03: marca editorial “Risco Cognitivo” (publicação riscocognitivo.org, canais @riscocognitivo) e framework técnico provisório “Cognitive Execution Risk Management — CERM”. ECO-05: curso “Gerenciando o TDAH Adulto” (I0) e e-books I1 “Aplicando o TDAH Adulto — Tutorial Prático”, I2 “TDAH Risk Management na Prática”, I3 “Gerenciando o TDAH Adulto / 360”. ECO-04: P0 “Executar Office Kit” (hero product), P1 “Executar Neurobook”, P2 “Timer 45”, P3 “Kit de Organização Física”. ECO-02: “Biblioteca Executar”. | H18: fato_interno | I18: alta | J18: TRANSVERSAL — nomes distintos por unidade | K18: DOC-C05-001;DOC-C04-002;DOC-C09-004;DOC-C09-011;DOC-C09-013;DOC-C09-008;DOC-C01-006;DOC-C02-016 | L18: DOC-C05-001: “Feature 01 — Agente 007 / Autogestão adaptativa”, “Feature 02 — Scanner / QR / Atalhos”, “Feature 03 — Mapa-OS / Analógico / Prisma”; Master Index dos infoprodutos I0–I4; Master Index — Produtos Físicos P0–P4. | DOC-C04-002: “PR #77 — feat(design-system): identidade única de tokens exec.*”; rotas “apps/app/app/(authenticated)/scanner/” e “/mapa-os?format=prisma (padrão, A4 retrato) e /mapa-os?format=tripe (A4 paisagem)”. | DOC-C01-006: “Risco Cognitivo → é a marca editorial; riscocognitivo.org → é a publicação/site; @riscocognitivo → são os canais da publicação.” | DOC-C02-016: “TÍTULO: Cognitive Execution Risk Management — v0.1”, com guardrail “Não reivindicar criação de ‘Cognitive Risk Management’”.
A19: 2 | B19: PRODUTO | C19: 2.2 | D19: Contexto do PRD | E19: formulario_original | F19: parcial | G19: Não existe PRD no corpus. O que existe é a base que antecede e alimenta um PRD, mais referências a PRDs que estão fora do conjunto documental. (a) Base: DATA-ADHD-PM-001 — “Matriz paralela Gestão de Projetos → exigência humana → vulnerabilidade associada ao TDAH → impacto operacional → compensação sistêmica → decisão de produto”, versão 1.0, de 19/08/2026, owner “Não determinado”, com o Next 01 explícito de “transformar a matriz em requisitos funcionais e princípios de design verificáveis”. (b) 22 decisões operacionais governadas (PROD-01…PROD-15 mais ICP-01, POSITION-01, PRICE-01, CAC-01, PMF-01, EFFICACY-01 e CLAIM-01), que funcionam como o contexto decisório que um PRD consumiria. (c) Referências a artefatos ausentes: DOC-C04-002 cita “PRD-006/UX-004” como critério de UX do Scanner e “OQ-008 do FRD original do Scanner” — nem o PRD-006 nem o FRD constam do inventário de 214 arquivos. | H19: fato_interno | I19: media | J19: ECO-01 | K19: DOC-C07-010;DOC-C07-009;DOC-C04-002;DOC-C07-002 | L19: DOC-C07-010: “ID DATA-ADHD-PM-001 · Tipo Pesquisa — Matriz de evidências e implicações de produto · Owner Não determinado · Versão 1.0 · Data 19/08/2026”; “Next 01 Transformar a matriz abaixo em requisitos funcionais e princípios de design verificáveis.” | DOC-C04-002: “Câmera compacta por padrão (PRD-006/UX-004: velocidade de captura antes de prévia grande)” e “Offline (OQ-008 do FRD original do Scanner) segue fora de escopo, nunca implementado.” | M19: Falta o PRD propriamente dito. Os documentos citam PRD-006 e um FRD do Scanner que não estão entre os 214 arquivos — provavelmente vivem no repositório Sas-Executar/Sas-Executar ou no Drive, não no conjunto entregue. | N19: Localizar PRD-006 e o FRD do Scanner no repositório/Drive e incorporá-los ao registro documental, ou declará-los inexistentes e escrever o PRD a partir de DATA-ADHD-PM-001.
A20: 2 | B20: PRODUTO | C20: 2.3 | D20: Objetivos (goals) | E20: formulario_original | F20: preenchido | G20: Objetivos por unidade. ECO-01 App: “transferir carga executiva evitável do operador para o sistema, preservando decisão e autonomia do usuário”; e “criar uma situação em que a execução do que foi planejado aconteça com o mínimo possível de carga administrativa e cognitiva”. ECO-03 Framework: “Investigar riscos cognitivos endógenos como vulnerabilidades capazes de aumentar a probabilidade de desvio entre intenção e execução”, com cinco componentes provisórios — Cognitive Risk Profile, Cognitive Demand Map, Cognitive Risk Register, Compensating Controls e Execution Evidence. ECO-02 Blog: “Publicar o artigo fundador e iniciar a campanha inaugural de 14 dias sem transformar a campanha em lançamento de produto”; objetivo SMART: “lançar Risco Cognitivo e validar interesse pela tese”. GTM 07/09 (transversal): 60h comprometidas + 12h de reserva em 12 dias produtivos (83% da capacidade), com tudo “produzido, integrado, configurado e agendado” até 05/09. ECO-05 Curso: quatro módulos Entender → Estruturar → Executar → Evoluir. ECO-02 site/CMS: autonomia editorial total, sem tocar em código. | H20: decisao | I20: alta | J20: TRANSVERSAL — objetivos distintos por unidade | K20: DOC-C07-002;DOC-C02-016;DOC-C02-014;DOC-C06-001;DOC-C09-013;DOC-C02-017 | L20: DOC-C07-002 (Tese operacional): “transferir carga executiva evitável do operador para o sistema, preservando decisão e autonomia do usuário.” | DOC-C02-016 (PROPOSIÇÃO): “Investigar riscos cognitivos endógenos como vulnerabilidades capazes de aumentar a probabilidade de desvio entre intenção e execução”; COMPONENTES PROVISÓRIOS 1–5. | DOC-C02-014 (OBJETIVO): “Publicar o artigo fundador e iniciar a campanha inaugural de 14 dias sem transformar a campanha em lançamento de produto.” | DOC-C06-001: “recomendação: 60h comprometidas + 12h de reserva (83% da capacidade)”. | DOC-C09-013: “4 módulos: Entender → Estruturar → Executar → Evoluir.”
A21: 2 | B21: PRODUTO | C21: 2.4 | D21: Não-objetivos (non-goals) | E21: formulario_original | F21: preenchido | G21: Não-objetivos explícitos e abundantes, por unidade. ECO-01: PROD-14 — “Bloquear usos do produto como diagnóstico, substituição profissional ou inferência clínica a partir de desempenho em tarefas”; CLAIM-01 proíbe “Reduz sintomas de TDAH”, “Melhora função executiva clinicamente”, “Trata TDAH”, “Diagnostica ou identifica TDAH”, “Substitui terapia, tratamento ou medicação” e “Cientificamente comprovado para TDAH”; POSITION-01 — “não como tratamento de TDAH”; EFFICACY-01 — “não iniciar com claim de redução de sintomas”. No código: “Offline (OQ-008) segue fora de escopo, nunca implementado”; e o primitivo concluirPorGestoHumano é “reservado DELIBERADAMENTE só para gesto humano direto — o Copiloto/IA continua passando por executarFerramenta”. Duas explorações de design foram registradas e deliberadamente NÃO adotadas: “Fractal Fluent” e “3PN + Good Path”. ECO-02: “O artigo não termina vendendo EXECUTAR”; “O CTA do D14 não deve vender EXECUTAR na campanha inaugural.” ECO-03: “Não reivindicar criação de ‘Cognitive Risk Management’”; não afirmar que “déficit de atenção” é termo abolido; não afirmar que pessoas neurotípicas não possuem riscos cognitivos. ECO-04: “Roupas — fora do escopo atual […] Não lançar agora”; “Não imobilizar estoque relevante antes de validar intenção.” ECO-07: tabela “Não é para” (quem busca tratamento de saúde, quem quer só uma dica rápida, projeto sem dono, escopo indefinido, grande transformação corporativa em sete dias); e “Eu não publicaria ‘consulta sem limite de tempo’ literalmente.” GTM 07/09: “Não é: Editar landing · Terminar vídeo · Produzir post · Cadastrar produto.” | H21: decisao | I21: alta | J21: TRANSVERSAL | K21: DOC-C07-009;DOC-C04-002;DOC-C02-043;DOC-C02-014;DOC-C02-016;DOC-C09-008;DOC-C05-001;DOC-C06-001 | L21: DOC-C07-009 (PROD-14): “Bloquear usos do produto como diagnóstico, substituição profissional ou inferência clínica a partir de desempenho em tarefas”; (claims_policy.prohibited_now): lista literal dos seis claims. | DOC-C04-002 (item 4e): “Offline (OQ-008 do FRD original do Scanner) segue fora de escopo, nunca implementado.”; e “Duas explorações de design JÁ REGISTRADAS no ecossistema e DELIBERADAMENTE NÃO ADOTADAS aqui”. | DOC-C02-043: “O artigo não termina vendendo EXECUTAR.” | DOC-C02-016 (GUARDRAIL): “Não reivindicar criação de ‘Cognitive Risk Management’.” | DOC-C09-008 (Regra): “Não imobilizar estoque relevante antes de validar intenção.” | DOC-C06-001 (07/09): “Não é: Editar landing · Terminar vídeo · Produzir post · Cadastrar produto. Se isso estiver acontecendo em 07/09, o Freeze falhou.”
A22: 2 | B22: PRODUTO | C22: 2.5 | D22: Requisitos funcionais (FRD) | E22: formulario_original | F22: preenchido | G22: Requisitos funcionais existem em dois níveis. (a) Componentes sistêmicos derivados da compensação (DOC-C05-001, item 16): “memória externa persistente, decomposição assistida, motor de prioridade, próxima ação, contexto persistente, throughput observado, sistema temporal, grafo de dependências, progresso automático, DoD e retomada de estado”; automações (item 18): “recalcular prioridades, filtrar elegibilidade, preservar contexto, atualizar progresso e selecionar a próxima ação”. Regras do motor: dependências, tempo, WIP e ciclo definem elegibilidade; Flow Score e Context Score ordenam as alternativas válidas; Progress Points registram somente trabalho efetivamente concluído. (b) Requisitos já implementados e verificáveis (DOC-C04-002): rota /scanner com reconhecimento de forma, sem QR, dos cinco símbolos administrativos entrada | copiloto | seletor | feito | saída; resolverPayloadScanner(payload); idempotencyKeyScanner com bucket de 10s contra duplo-scan acidental; Undo com janela de 8s restaurando o EstadoOperacional anterior via expectedRevision (concorrência otimista); rota /mapa-os com projetarMapaOS — projeção pura, “nenhum estado novo” — nos formatos prisma (A4 retrato) e tripé (A4 paisagem); primitivo concluirPorGestoHumano, que ignora requireDod, requireEvidence, requireHumanApproval e requireVerification mesmo sob POLITICA_CONCLUSAO_PADRAO, mas apenas para gesto humano direto e mantendo registro auditável no event log; toda mutação oficial passa por executarFerramenta, com idempotência e replay via run-ledger. (c) Requisitos de UX derivados das decisões PROD-05 e PROD-09…PROD-13: uma única próxima ação principal explícita; nos primeiros segundos mostrar estado atual, resultado necessário e próxima ação; persistir contexto e posição de execução para retomada; interromper apenas por evento crítico; exigir confirmação só em ações irreversíveis. | H22: fato_interno | I22: alta | J22: ECO-01 | K22: DOC-C04-002;DOC-C05-001;DOC-C07-009;DOC-C11-006;DOC-C11-004 | L22: DOC-C04-002: “idempotencyKeyScanner(organizationId, acao, alvo, nowMs) → bucket de 10s, evita duplo-scan acidental”; “Undo: janela de 8s, restaura o EstadoOperacional anterior via o mesmo endpoint de salvar estado com expectedRevision”; “concluirPorGestoHumano(tasks, state, taskId, nota) — Ignora TODAS as flags de PoliticaConclusao […] Reservado DELIBERADAMENTE só para gesto humano direto”. | DOC-C05-001 (item 16 Componentes sistêmicos): lista literal dos onze componentes. | DOC-C07-009 (PROD-09): “A interface deve tornar explícita uma única próxima ação principal e esconder complexidade secundária até ser necessária.” | M22: Não há FRD consolidado: os requisitos estão distribuídos entre handoff técnico, workbook e decisões. O Scanner mobile (Expo) só é validável em device físico e não foi testado além de typecheck/build. | N22: Consolidar os requisitos dispersos num FRD único e validar o Scanner mobile em device físico antes do lançamento.
A23: 2 | B23: PRODUTO | C23: 2.6 | D23: Critérios de aceite | E23: formulario_original | F23: preenchido | G23: Critérios de aceite existem em cinco camadas. (a) DoD editorial do GTM: “texto aprovado + assets presentes + CTA funcional + brinde funcional + CMS carregado + SEO preenchido + links testados + publicação/agendamento confirmado + evidência registrada”, sobre a cadeia de pacote “conteúdo → assets → CTA → brinde → destino → CMS → distribuição → agendamento → tracking → evidência = DONE”. (b) Critérios de lançamento de 05/09 (dez itens): páginas críticas abrem em celular e computador; todas as chamadas chegam ao destino correto; formulários recebem respostas; ofertas digitais estão cadastradas; ligações de afiliado estão identificadas; peças editoriais publicadas ou agendadas; demonstrações acessíveis; materiais para redes agendados; medição básica funcionando; não existe entrega crítica aguardando produção. (c) DoD técnico verificado: typecheck limpo, bun run check limpo, 51/51 testes vitest, 347/347 testes de governança e 3/3 checks de CI verdes por PR. (d) DoD do site/CMS: “Abrir /admin → criar artigo → escrever/colar → categorizar → inserir imagem → preencher SEO → ver palavras/parágrafos → preview → publicar, sem editar código.” (e) Critério de conclusão do ECO-02: “Artigo 1.200–1.800 palavras publicado, landing disponível, CTA editorial funcionando e cronograma D1–D14 iniciado.” Princípio de produto que rege todos: “DONE deve ser uma transição verificável, não uma sensação de conclusão.” | H23: fato_interno | I23: alta | J23: TRANSVERSAL | K23: DOC-C06-001;DOC-C08-007;DOC-C04-002;DOC-C02-017;DOC-C02-014;DOC-C07-002;DOC-C10-010;DOC-C10-018;DOC-C10-026 | L23: DOC-C06-001: “Definition of Done editorial: texto aprovado + assets presentes + CTA funcional + brinde funcional + CMS carregado + SEO preenchido + links testados + publicação/agendamento confirmado + evidência registrada.” | DOC-C08-007: lista literal dos dez critérios de congelamento de 05/09. | DOC-C04-002: “bun run --filter=app test (vitest) → 51/51 passando”; “node --test tests/ondas/*.test.mjs (governança) → 347/347 passando”. | DOC-C02-017 (DEFINITION OF DONE): “Abrir /admin → criar artigo → […] → publicar, sem editar código.” | DOC-C07-002 (GP-10, decisão de produto): “DONE deve ser uma transição verificável, não uma sensação de conclusão.” | DOC-C10-010/018/026: “Concluído quando: A peça está publicada ou programada, com materiais, chamada, destino e evidência registrados.”
A24: 2 | B24: PRODUTO | C24: 2.7 | D24: Persona principal | E24: formulario_original | F24: parcial | G24: Não há artefato de persona (nome, cenário, objetivos, frustrações) em nenhum documento. O que existe são duas descrições de ICP em conflito — as mesmas do campo 1.2 — acrescidas de perspectivas em primeira pessoa que funcionam como matéria-prima de persona. Versão A (DOC-C05-001): “Homens, adultos, neurodivergentes, autônomos, na faixa dos 25–35 anos, recém-diagnosticados, que gerenciam múltiplos processos e projetos ao mesmo tempo […] já utilizaram e abandonaram outros aplicativos por não manterem o uso e rejeitam alta complexidade de configuração.” Versão B (DOC-C07-009, ICP-01): “profissional independente/solo brasileiro, aproximadamente 25–44 anos, multiprojeto, que perde contexto, tem dificuldade recorrente para escolher próxima ação, já tentou ferramentas de produtividade e controla/influencia a própria compra”, sem exigir diagnóstico. Persona do ECO-07 documentada em separado: “profissionais solo, autônomos e pequenos negócios com trabalho, informação, clientes e projetos dispersos”, com tabela “É para / Não é para”. | H24: hipotese | I24: media | J24: ECO-01 (com persona própria em ECO-07) | K24: DOC-C05-001;DOC-C07-009;DOC-C12-003 | L24: DOC-C05-001 (Corpo, linha Público): texto integral da versão A, com a perspectiva do usuário “Quero começar o dia, semana, mês de trabalho executando as tarefas sem, ao mesmo tempo, me preocupar com a ordem e controle da progressão.” | DOC-C07-009 (ICP comercial a testar): texto integral da versão B, com “Decisão ICP-01: testar comportamento e problema primeiro; diagnóstico não define o ICP comercial inicial.” | DOC-C12-003: dez perguntas do formulário de entrada do Estúdio, que operacionalizam o perfil (como trabalha hoje, principal atrito, ferramentas atuais, dificuldade de retomada, relação com papel/físico). | M24: Falta a persona formalizada, e falta resolver o conflito de ICP (faixa etária 25–35 × 25–44, gênero, papel do diagnóstico). O artefato estaria num documento de pesquisa de usuário/persona — inexistente; e a própria decisão ICP-01 tem status DECIDED_FOR_TEST, isto é, hipótese a validar em recrutamento. | N24: Resolver o conflito de ICP e escrever uma persona única derivada da versão vencedora; ICP-01 já prevê “recrutar ICP comportamental e medir ativação, recorrência, pagamento e retenção”.
A25: 2 | B25: PRODUTO | C25: 2.8 | D25: Jornada — Descoberta | E25: formulario_original | F25: parcial | G25: A jornada de descoberta está desenhada para os eixos editorial e de serviços, não para o app. Editorial (ECO-02): a descoberta é governada por níveis de consciência — “Não consciente → consciente do problema → consciente das soluções → consciente do método → pronto para agir” — com CTA correspondente por nível (“Baixa consciência: não empurre Produto; CTA ideal ‘Entenda o que está acontecendo’”; “Alta intenção: não empurre mais teoria; CTA ‘Experimentar Executar / conhecer Studio’”). O artigo canônico é a peça-mãe e cada peça segue a narrativa “CENA → PROBLEMA → MECANISMO → EVIDÊNCIA → MODELO → APLICAÇÃO → DEMONSTRAÇÃO → PRÓXIMO PASSO”. A campanha inaugural do ECO-02 vai de D1 (artigo + landing) a D14 (síntese + CTA editorial), com CTA “ler, explorar, assinar e baixar o Mapa de Risco Cognitivo” e o produto deliberadamente em segundo plano. Serviços (ECO-07): “Conteúdo → Showroom → Formulário visual → Encontro → Projeto”, com regra de showroom “Problema → entrada real → transformação → resultado → prova → CTA”. Porta de entrada de captação: brinde canônico BRINDE-001/GIFT-001, com cadeia “asset → capa → landing → formulário → confirmação → entrega/download → CTA → tracking → evidence”. | H25: decisao | I25: media | J25: ECO-02 e ECO-07 documentadas; ECO-01 sem jornada de descoberta própria | K25: DOC-C05-001;DOC-C02-043;DOC-C06-001;DOC-C10-029;DOC-C11-010;DOC-C12-004 | L25: DOC-C05-001 (CTA por nível de consciência): “Baixa | não empurre Produto | CTA ideal Entenda o que está acontecendo”; “Alta intenção | não empurre Mais teoria | CTA Experimentar Executar / conhecer Studio.” | DOC-C05-001 (Showroom — regra geral): “Problema → entrada real → transformação → resultado → prova → CTA. Não faça vídeos ‘Veja meu agente incrível’.” | DOC-C02-043: “CTA inicial: ler, explorar, assinar e baixar o Mapa de Risco Cognitivo; o EXECUTAR fica para uma campanha posterior.” | DOC-C10-029: “asset → capa → landing → formulário → confirmação → entrega/download → CTA → tracking → evidence” (cadeia do brinde). | M25: Falta a jornada de descoberta específica do app: como um usuário chega ao EXECUTAR (loja de apps, landing, indicação) não está documentado. Os eventos acquisition_source e campaign_id existem como especificação de telemetria, sem mapa de jornada correspondente. | N25: Desenhar a jornada de descoberta do ECO-01 ligando os CTAs CH-001/CH-002 aos eventos acquisition_source e install_or_signup.
